File: SHT 046(TEXT).txt
*RAS_DATA_START
*RAS_HEADER_START
*DISP_FMT_X "%.3f"
*DISP_FMT_Y "%.0f"
*DISP_FULLSCALE "277.0206900458"
*DISP_LINE_COLOR "255.0000000000"
*DISP_LINE_STYLE "0.0000000000"
*DISP_LINE_WIDTH "0.2500000000"
*DISP_NOTE "測定データ-1"
*DISP_OFFSET_Y "0.0000000000"
*DISP_PEAKSEARCH_UNIT_Y "cps"
*DISP_RANGE_BOTTOM "0.0000000000"
*DISP_RANGE_LEFT "5.0000000000"
*DISP_RANGE_LOGCUTOFF "0.0100000000"
*DISP_RANGE_RIGHT "79.9930000000"
*DISP_RANGE_TOP "277.0206900458"
*DISP_SCALE_MODE_Y "0.0000000000"
*DISP_TAB_NAME "2θ/ω"
*DISP_TITLE_Y "強度"
*DISP_UNIT_Y "cps"
*DISP_WINDOW_NAME "MSG_MACROENGINE"
*FILE_COMMENT " "
*FILE_MD5 ""
*FILE_MEMO " "
*FILE_OPERATOR "administrator"
*FILE_PART_ID "MEAS_KHP2_00061"
*FILE_SAMPLE " "
*FILE_TYPE "RAS_RAW"
*FILE_USERGROUP "システムマネージャ"
*FILE_VERSION "1.0000000000"
*HW_ATTACHMENT_ID "ATT0025"
*HW_ATTACHMENT_NAME "標準|Standard"
*HW_COUNTER_ID-0 "CUT0021"
*HW_COUNTER_ID-1 "CUT0051"
*HW_COUNTER_ID-2 "CUT0020"
*HW_COUNTER_ID-3 "CSL0021"
*HW_COUNTER_ID-4 "CMC0021"
*HW_COUNTER_NAME-0 "SC-70|SC-70"
*HW_COUNTER_NAME-1 "HyPix 3000(H)|HyPix 3000(H)"
*HW_COUNTER_NAME-2 "None|None"
*HW_COUNTER_NAME-3 "BBM|BBM"
*HW_COUNTER_NAME-4 "検出器モノクロメータ|Detector monochromator"
*HW_COUNTER_SELECT_NAME "HyPix 3000(H)|HyPix 3000(H)"
*HW_GONIOMETER_ID "GON0023"
*HW_GONIOMETER_NAME "SmartLab|SmartLab"
*HW_GONIOMETER_RADIUS-0 "90.0"
*HW_GONIOMETER_RADIUS-1 "114.0"
*HW_GONIOMETER_RADIUS-2 "190.0"
*HW_GONIOMETER_RADIUS-3 "300.0"
*HW_GONIOMETER_RADIUS-4 "187.0"
*HW_GONIOMETER_RADIUS-5 "300.0"
*HW_GONIOMETER_RADIUS-6 "113.0"
*HW_GONIOMETER_RADIUS-7 "331.0"
*HW_I_OPT_ID-0 "CBO0021"
*HW_I_OPT_ID-1 "ICR0023"
*HW_I_OPT_ID-2 "ISL0021"
*HW_I_OPT_ID-3 "ISO0021"
*HW_I_OPT_ID-4 "IAD0021"
*HW_I_OPT_ID-5 "IPR0002"
*HW_I_OPT_NAME-0 "CBOユニット|CBO unit"
*HW_I_OPT_NAME-1 "標準入射光学ユニット|Standard incident optical unit"
*HW_I_OPT_NAME-2 "標準入射スリットボックス|Standard incident slit box"
*HW_I_OPT_NAME-3 "入射平行スリット|Incident parallel slit"
*HW_I_OPT_NAME-4 "長手制限スリット|Length limiting slit"
*HW_I_OPT_NAME-5 "Ka1|Ka1"
*HW_R_ATTENUATER_AUTOMODE "0"
*HW_R_OPT_ID-0 "RSS0022"
*HW_R_OPT_ID-1 "RCR0022"
*HW_R_OPT_ID-2 "RSO0021"
*HW_R_OPT_ID-3 "RRS0022"
*HW_R_OPT_ID-4 "ATN0020"
*HW_R_OPT_ID-5 "RFL0021"
*HW_R_OPT_ID-6 "RAD0021"
*HW_R_OPT_NAME-0 "受光スリットボックス1(Zr軸付)|Receiving slit box # 1 (w/ Zr Axis)"
*HW_R_OPT_NAME-1 "標準受光光学ユニット1|Standard receiving unit # 1"
*HW_R_OPT_NAME-2 "標準受光光学ユニット2|Standard receiving optical unit # 2"
*HW_R_OPT_NAME-3 "標準受光スリットボックス2|Standard receiving slit box # 2"
*HW_R_OPT_NAME-4 "無し|None"
*HW_R_OPT_NAME-5 "Cu Kβ|Cu K-beta"
*HW_R_OPT_NAME-6 "調整用受光スリット|Alignment receiving slit"
*HW_SAMPLE_HOLDER_ID "SMP0023"
*HW_SAMPLE_HOLDER_NAME "標準Zステージ|Standard Z stage"
*HW_XG_CURRENT_MAX "200"
*HW_XG_CURRENT_MIN "10"
*HW_XG_CURRENT_RESOLUTION "2"
*HW_XG_CURRENT_UNIT "mA"
*HW_XG_FOCUS ""
*HW_XG_FOCUS_TYPE "Normal"
*HW_XG_ID ""
*HW_XG_NAME "9kW 開放管(45kV 200mA ID:1700)|9kW Rotating anode(45kV 200mA ID:1700)"
*HW_XG_TARGET_ATOMIC_NUMBER "29.0000000000"
*HW_XG_TARGET_NAME "Cu"
*HW_XG_TYPE "Rota"
*HW_XG_VOLTAGE_MAX "45"
*HW_XG_VOLTAGE_MIN "20"
*HW_XG_VOLTAGE_RESOLUTION "2"
*HW_XG_VOLTAGE_UNIT "kV"
*HW_XG_WATT_MAX "9"
*HW_XG_WATT_UNIT "kW"
*HW_XG_WAVE_LENGTH_ALPHA1 "1.540593"
*HW_XG_WAVE_LENGTH_ALPHA2 "1.544414"
*HW_XG_WAVE_LENGTH_BETA "1.392250"
*MEAS_COND_AXIS_NAME-0 "2θ/θ"
*MEAS_COND_AXIS_NAME-1 "2θ"
*MEAS_COND_AXIS_NAME-2 "ω"
*MEAS_COND_AXIS_NAME-3 "Z"
*MEAS_COND_AXIS_NAME-4 "2θ/ω"
*MEAS_COND_AXIS_NAME-5 "θs"
*MEAS_COND_AXIS_NAME-6 "θd"
*MEAS_COND_AXIS_NAME-7 "Ts"
*MEAS_COND_AXIS_NAME-8 "CBO選択スリット"
*MEAS_COND_AXIS_NAME-9 "M"
*MEAS_COND_AXIS_NAME-10 "入射平行スリット"
*MEAS_COND_AXIS_NAME-11 "入射スリット"
*MEAS_COND_AXIS_NAME-12 ""
*MEAS_COND_AXIS_NAME-13 "Zs"
*MEAS_COND_AXIS_NAME-14 "入射光学素子"
*MEAS_COND_AXIS_NAME-15 "長手制限スリット"
*MEAS_COND_AXIS_NAME-16 "センタースリット"
*MEAS_COND_AXIS_NAME-17 "フィルター"
*MEAS_COND_AXIS_NAME-18 "受光スリット1"
*MEAS_COND_AXIS_NAME-19 "受光スリット2"
*MEAS_COND_AXIS_NAME-20 "受光光学素子"
*MEAS_COND_AXIS_NAME-21 "受光平行スリット"
*MEAS_COND_AXIS_NAME-22 "調整用受光スリット"
*MEAS_COND_AXIS_NAME-23 ""
*MEAS_COND_AXIS_NAME-24 ""
*MEAS_COND_AXIS_NAME-25 "Zd"
*MEAS_COND_AXIS_NAME-26 "アッテネータ"
*MEAS_COND_AXIS_NAME-27 "検出器モノクロメータ"
*MEAS_COND_AXIS_NAME-28 "モノクロメータスリット"
*MEAS_COND_AXIS_NAME-29 "Zr"
*MEAS_COND_AXIS_NAME-30 "プライマリビーム"
*MEAS_COND_AXIS_NAME-31 "Ma"
*MEAS_COND_AXIS_NAME_INTERNAL-0 "TwoThetaTheta"
*MEAS_COND_AXIS_NAME_INTERNAL-1 "TwoTheta"
*MEAS_COND_AXIS_NAME_INTERNAL-2 "Omega"
*MEAS_COND_AXIS_NAME_INTERNAL-3 "Z"
*MEAS_COND_AXIS_NAME_INTERNAL-4 "TwoThetaOmega"
*MEAS_COND_AXIS_NAME_INTERNAL-5 "ThetaS"
*MEAS_COND_AXIS_NAME_INTERNAL-6 "ThetaD"
*MEAS_COND_AXIS_NAME_INTERNAL-7 "Ts"
*MEAS_COND_AXIS_NAME_INTERNAL-8 "CBO"
*MEAS_COND_AXIS_NAME_INTERNAL-9 "CBO-M"
*MEAS_COND_AXIS_NAME_INTERNAL-10 "IncidentSollerSlit"
*MEAS_COND_AXIS_NAME_INTERNAL-11 "IncidentSlitBox"
*MEAS_COND_AXIS_NAME_INTERNAL-12 "IncidentSlitBox-_Axis"
*MEAS_COND_AXIS_NAME_INTERNAL-13 "Zs"
*MEAS_COND_AXIS_NAME_INTERNAL-14 "IncidentMonochromator"
*MEAS_COND_AXIS_NAME_INTERNAL-15 "IncidentAxdSlit"
*MEAS_COND_AXIS_NAME_INTERNAL-16 "CenterSlit"
*MEAS_COND_AXIS_NAME_INTERNAL-17 "Filter"
*MEAS_COND_AXIS_NAME_INTERNAL-18 "ReceivingSlitBox1"
*MEAS_COND_AXIS_NAME_INTERNAL-19 "ReceivingSlitBox2"
*MEAS_COND_AXIS_NAME_INTERNAL-20 "ReceivingOptics"
*MEAS_COND_AXIS_NAME_INTERNAL-21 "ReceivingSollerSlit"
*MEAS_COND_AXIS_NAME_INTERNAL-22 "ReceivingAxdSlit"
*MEAS_COND_AXIS_NAME_INTERNAL-23 "ReceivingSlitBox1-_Axis"
*MEAS_COND_AXIS_NAME_INTERNAL-24 "ReceivingSlitBox2-_Axis"
*MEAS_COND_AXIS_NAME_INTERNAL-25 "ReceivingSlitBox2-Zd"
*MEAS_COND_AXIS_NAME_INTERNAL-26 "Attenuator"
*MEAS_COND_AXIS_NAME_INTERNAL-27 "CounterMonochromator"
*MEAS_COND_AXIS_NAME_INTERNAL-28 "CounterSlit"
*MEAS_COND_AXIS_NAME_INTERNAL-29 "ReceivingSlitBox1-Zr"
*MEAS_COND_AXIS_NAME_INTERNAL-30 "IncidentPrimary"
*MEAS_COND_AXIS_NAME_INTERNAL-31 "IncidentPrimary-Ma"
*MEAS_COND_AXIS_NAME_MAGICNO-0 "83951616.0000000000"
*MEAS_COND_AXIS_NAME_MAGICNO-1 "268632064.0000000000"
*MEAS_COND_AXIS_NAME_MAGICNO-2 "268500992.0000000000"
*MEAS_COND_AXIS_NAME_MAGICNO-3 "285278208.0000000000"
*MEAS_COND_AXIS_NAME_MAGICNO-4 "83951616.0000000000"
*MEAS_COND_AXIS_NAME_MAGICNO-5 "131072.0000000000"
*MEAS_COND_AXIS_NAME_MAGICNO-6 "131072.0000000000"
*MEAS_COND_AXIS_NAME_MAGICNO-7 "318898176.0000000000"
*MEAS_COND_AXIS_NAME_MAGICNO-8 "20971521.0000000000"
*MEAS_COND_AXIS_NAME_MAGICNO-9 "285343744.0000000000"
*MEAS_COND_AXIS_NAME_MAGICNO-10 "20971521.0000000000"
*MEAS_COND_AXIS_NAME_MAGICNO-11 "22020097.0000000000"
*MEAS_COND_AXIS_NAME_MAGICNO-12 "25165824.0000000000"
*MEAS_COND_AXIS_NAME_MAGICNO-13 "318898176.0000000000"
*MEAS_COND_AXIS_NAME_MAGICNO-14 "1.0000000000"
*MEAS_COND_AXIS_NAME_MAGICNO-15 "20971521.0000000000"
*MEAS_COND_AXIS_NAME_MAGICNO-16 "20971521.0000000000"
*MEAS_COND_AXIS_NAME_MAGICNO-17 "20971521.0000000000"
*MEAS_COND_AXIS_NAME_MAGICNO-18 "23068673.0000000000"
*MEAS_COND_AXIS_NAME_MAGICNO-19 "23068673.0000000000"
*MEAS_COND_AXIS_NAME_MAGICNO-20 "20971521.0000000000"
*MEAS_COND_AXIS_NAME_MAGICNO-21 "20971521.0000000000"
*MEAS_COND_AXIS_NAME_MAGICNO-22 "20971521.0000000000"
*MEAS_COND_AXIS_NAME_MAGICNO-23 "25165824.0000000000"
*MEAS_COND_AXIS_NAME_MAGICNO-24 "25165824.0000000000"
*MEAS_COND_AXIS_NAME_MAGICNO-25 "285343744.0000000000"
*MEAS_COND_AXIS_NAME_MAGICNO-26 "0.0000000000"
*MEAS_COND_AXIS_NAME_MAGICNO-27 "20971521.0000000000"
*MEAS_COND_AXIS_NAME_MAGICNO-28 "20971521.0000000000"
*MEAS_COND_AXIS_NAME_MAGICNO-29 "285343744.0000000000"
*MEAS_COND_AXIS_NAME_MAGICNO-30 "20971521.0000000000"
*MEAS_COND_AXIS_NAME_MAGICNO-31 "285343744.0000000000"
*MEAS_COND_AXIS_OFFSET-0 "-"
*MEAS_COND_AXIS_OFFSET-1 "0.1521000000"
*MEAS_COND_AXIS_OFFSET-2 "0.1635000000"
*MEAS_COND_AXIS_OFFSET-3 "-"
*MEAS_COND_AXIS_OFFSET-4 "-"
*MEAS_COND_AXIS_OFFSET-5 "0.1635000000"
*MEAS_COND_AXIS_OFFSET-6 "-0.0114000000"
*MEAS_COND_AXIS_OFFSET-7 "-"
*MEAS_COND_AXIS_OFFSET-8 "-"
*MEAS_COND_AXIS_OFFSET-9 "-"
*MEAS_COND_AXIS_OFFSET-10 "-"
*MEAS_COND_AXIS_OFFSET-11 "-"
*MEAS_COND_AXIS_OFFSET-12 "-"
*MEAS_COND_AXIS_OFFSET-13 "-"
*MEAS_COND_AXIS_OFFSET-14 "-"
*MEAS_COND_AXIS_OFFSET-15 "-"
*MEAS_COND_AXIS_OFFSET-16 "-"
*MEAS_COND_AXIS_OFFSET-17 "-"
*MEAS_COND_AXIS_OFFSET-18 "-"
*MEAS_COND_AXIS_OFFSET-19 "-"
*MEAS_COND_AXIS_OFFSET-20 "-"
*MEAS_COND_AXIS_OFFSET-21 "-"
*MEAS_COND_AXIS_OFFSET-22 "-"
*MEAS_COND_AXIS_OFFSET-23 "-"
*MEAS_COND_AXIS_OFFSET-24 "-"
*MEAS_COND_AXIS_OFFSET-25 "-"
*MEAS_COND_AXIS_OFFSET-26 "-"
*MEAS_COND_AXIS_OFFSET-27 "-"
*MEAS_COND_AXIS_OFFSET-28 "-"
*MEAS_COND_AXIS_OFFSET-29 "-"
*MEAS_COND_AXIS_OFFSET-30 "-"
*MEAS_COND_AXIS_OFFSET-31 "-"
*MEAS_COND_AXIS_POSITION-0 "0.0000000000"
*MEAS_COND_AXIS_POSITION-1 "0.0000000000"
*MEAS_COND_AXIS_POSITION-2 "0.0000000000"
*MEAS_COND_AXIS_POSITION-3 "-0.0500000000"
*MEAS_COND_AXIS_POSITION-4 "0.0000000000"
*MEAS_COND_AXIS_POSITION-5 "0.0000000000"
*MEAS_COND_AXIS_POSITION-6 "0.0000000000"
*MEAS_COND_AXIS_POSITION-7 "0.6961900000"
*MEAS_COND_AXIS_POSITION-8 "BB"
*MEAS_COND_AXIS_POSITION-9 "0.0000000000"
*MEAS_COND_AXIS_POSITION-10 "Soller_slit_5.0deg"
*MEAS_COND_AXIS_POSITION-11 "1.000deg"
*MEAS_COND_AXIS_POSITION-12 "3.3163000000"
*MEAS_COND_AXIS_POSITION-13 "0.2993800000"
*MEAS_COND_AXIS_POSITION-14 "0.0000000000"
*MEAS_COND_AXIS_POSITION-15 "10.0mm"
*MEAS_COND_AXIS_POSITION-16 "None"
*MEAS_COND_AXIS_POSITION-17 "None"
*MEAS_COND_AXIS_POSITION-18 "1.000mm"
*MEAS_COND_AXIS_POSITION-19 "1.100mm"
*MEAS_COND_AXIS_POSITION-20 "PSA_open"
*MEAS_COND_AXIS_POSITION-21 "Soller_slit_5.0deg"
*MEAS_COND_AXIS_POSITION-22 "None"
*MEAS_COND_AXIS_POSITION-23 "1.0000000000"
*MEAS_COND_AXIS_POSITION-24 "1.1000000000"
*MEAS_COND_AXIS_POSITION-25 "0.0000000000"
*MEAS_COND_AXIS_POSITION-26 "-"
*MEAS_COND_AXIS_POSITION-27 "No_unit"
*MEAS_COND_AXIS_POSITION-28 "None"
*MEAS_COND_AXIS_POSITION-29 "0.1015600000"
*MEAS_COND_AXIS_POSITION-30 "Johansson(Ka1)"
*MEAS_COND_AXIS_POSITION-31 "0.0000000000"
*MEAS_COND_AXIS_UNIT-0 "deg"
*MEAS_COND_AXIS_UNIT-1 "deg"
*MEAS_COND_AXIS_UNIT-2 "deg"
*MEAS_COND_AXIS_UNIT-3 "mm"
*MEAS_COND_AXIS_UNIT-4 "deg"
*MEAS_COND_AXIS_UNIT-5 "deg"
*MEAS_COND_AXIS_UNIT-6 "deg"
*MEAS_COND_AXIS_UNIT-7 "mm"
*MEAS_COND_AXIS_UNIT-8 ""
*MEAS_COND_AXIS_UNIT-9 "pulse"
*MEAS_COND_AXIS_UNIT-10 ""
*MEAS_COND_AXIS_UNIT-11 ""
*MEAS_COND_AXIS_UNIT-12 "mm"
*MEAS_COND_AXIS_UNIT-13 "mm"
*MEAS_COND_AXIS_UNIT-14 ""
*MEAS_COND_AXIS_UNIT-15 ""
*MEAS_COND_AXIS_UNIT-16 ""
*MEAS_COND_AXIS_UNIT-17 ""
*MEAS_COND_AXIS_UNIT-18 ""
*MEAS_COND_AXIS_UNIT-19 ""
*MEAS_COND_AXIS_UNIT-20 ""
*MEAS_COND_AXIS_UNIT-21 ""
*MEAS_COND_AXIS_UNIT-22 ""
*MEAS_COND_AXIS_UNIT-23 "mm"
*MEAS_COND_AXIS_UNIT-24 "mm"
*MEAS_COND_AXIS_UNIT-25 "mm"
*MEAS_COND_AXIS_UNIT-26 ""
*MEAS_COND_AXIS_UNIT-27 ""
*MEAS_COND_AXIS_UNIT-28 ""
*MEAS_COND_AXIS_UNIT-29 "mm"
*MEAS_COND_AXIS_UNIT-30 ""
*MEAS_COND_AXIS_UNIT-31 "pulse"
*MEAS_COND_COUNTER_CNTLOSS_CORR "0.0000000000"
*MEAS_COND_COUNTER_TAUDIFF "0.0000000000"
*MEAS_COND_COUNTER_TAUINT "0.0000000000"
*MEAS_COND_COUNTER_TEMP_CONDITION "NORMAL"
*MEAS_COND_IRRADIATION_MODE "OFF"
*MEAS_COND_IRRADIATION_WIDTH ""
*MEAS_COND_OPT_ATTR "集中法"
*MEAS_COND_OPT_NAME "@集中法"
*MEAS_COND_UNSYMMETRIC_MODE "OFF"
*MEAS_COND_XG_CURRENT "200.0000000000"
*MEAS_COND_XG_VOLTAGE "45.0000000000"
*MEAS_COND_XG_WAVE_TYPE "Ka1"
*MEAS_DATA_COUNT "7499.0000000000"
*MEAS_SCAN_AXIS_X "2θ/ω"
*MEAS_SCAN_AXIS_X_INTERNAL "TwoThetaOmega"
*MEAS_SCAN_END_TIME "05/09/23 10:26:32"
*MEAS_SCAN_MODE "CONTINUOUS"
*MEAS_SCAN_MONITOR "0"
*MEAS_SCAN_RESOLUTION_X "0.0002"
*MEAS_SCAN_SPEED "2.012958"
*MEAS_SCAN_SPEED_UNIT "deg/min"
*MEAS_SCAN_SPEED_USER "2.000000"
*MEAS_SCAN_START "5.0000000000"
*MEAS_SCAN_START_TIME "05/09/23 09:48:41"
*MEAS_SCAN_STEP "0.0100000000"
*MEAS_SCAN_STOP "79.9800000000"
*MEAS_SCAN_UNIT_X "deg"
*MEAS_SCAN_UNIT_Y "counts"
*RAS_HEADER_END
*RAS_INT_START
5.0000 5.2243 1.0000
5.0500 5.4162 1.0000
5.1000 7.1842 1.0000
5.1500 6.1118 1.0000
5.2000 6.2089 1.0000
5.2500 6.0892 1.0000
5.3000 4.1678 1.0000
5.3500 6.1271 1.0000
5.4000 4.1307 1.0000
5.4500 4.0673 1.0000
5.5000 6.0075 1.0000
5.5500 5.1587 1.0000
5.6000 4.8722 1.0000
5.6500 3.1561 1.0000
5.7000 4.2885 1.0000
5.7500 3.6758 1.0000
5.8000 3.1701 1.0000
5.8500 3.7664 1.0000
5.9000 2.2970 1.0000
5.9500 5.0205 1.0000
6.0000 4.2505 1.0000
6.0500 5.5745 1.0000
6.1000 5.3737 1.0000
6.1500 6.7687 1.0000
6.2000 3.7008 1.0000
6.2500 2.3769 1.0000
6.3000 4.3888 1.0000
6.3500 4.1747 1.0000
6.4000 6.2393 1.0000
6.4500 6.2134 1.0000
6.5000 4.7363 1.0000
6.5500 2.0359 1.0000
6.6000 5.7011 1.0000
6.6500 2.6890 1.0000
6.7000 2.4496 1.0000
6.7500 3.6467 1.0000
6.8000 4.4115 1.0000
6.8500 2.6584 1.0000
6.9000 3.7501 1.0000
6.9500 4.9986 1.0000
7.0000 3.4267 1.0000
7.0500 3.3261 1.0000
7.1000 3.9425 1.0000
7.1500 4.0906 1.0000
7.2000 3.2326 1.0000
7.2500 2.9504 1.0000
7.3000 4.9040 1.0000
7.3500 3.1496 1.0000
7.4000 4.2121 1.0000
7.4500 3.5281 1.0000
7.5000 2.8733 1.0000
7.5500 3.6321 1.0000
7.6000 2.5465 1.0000
7.6500 3.1670 1.0000
7.7000 2.7356 1.0000
7.7500 1.9533 1.0000
7.8000 2.2914 1.0000
7.8500 3.6634 1.0000
7.9000 1.4372 1.0000
7.9500 3.2300 1.0000
8.0000 3.4867 1.0000
8.0500 3.0123 1.0000
8.1000 4.5284 1.0000
8.1500 1.9423 1.0000
8.2000 2.4429 1.0000
8.2500 3.0603 1.0000
8.3000 2.4035 1.0000
8.3500 3.1116 1.0000
8.4000 1.7785 1.0000
8.4500 1.9043 1.0000
8.5000 4.5108 1.0000
8.5500 4.0170 1.0000
8.6000 4.2370 1.0000
8.6500 2.5209 1.0000
8.7000 2.9889 1.0000
8.7500 2.8159 1.0000
8.8000 0.9007 1.0000
8.8500 1.7940 1.0000
8.9000 2.8230 1.0000
8.9500 2.7083 1.0000
9.0000 1.8749 1.0000
9.0500 3.1597 1.0000
9.1000 3.7681 1.0000
9.1500 2.8617 1.0000
9.2000 2.0810 1.0000
9.2500 2.6977 1.0000
9.3000 2.2887 1.0000
9.3500 2.1966 1.0000
9.4000 3.8184 1.0000
9.4500 4.1872 1.0000
9.5000 1.4550 1.0000
9.5500 3.3248 1.0000
9.6000 3.1004 1.0000
9.6500 3.3403 1.0000
9.7000 2.9817 1.0000
9.7500 3.2883 1.0000
9.8000 1.5077 1.0000
9.8500 1.3186 1.0000
9.9000 1.3377 1.0000
9.9500 3.7082 1.0000
10.0000 3.6267 1.0000
10.0500 1.4327 1.0000
10.1000 2.2573 1.0000
10.1500 1.8924 1.0000
10.2000 3.5065 1.0000
10.2500 4.4637 1.0000
10.3000 2.1680 1.0000
10.3500 2.1572 1.0000
10.4000 2.4931 1.0000
10.4500 3.0455 1.0000
10.5000 0.5339 1.0000
10.5500 2.5274 1.0000
10.6000 2.7803 1.0000
10.6500 1.4247 1.0000
10.7000 2.9773 1.0000
10.7500 1.9568 1.0000
10.8000 2.9200 1.0000
10.8500 1.5233 1.0000
10.9000 0.7016 1.0000
10.9500 1.8561 1.0000
11.0000 2.0254 1.0000
11.0500 2.9906 1.0000
11.1000 2.6035 1.0000
11.1500 1.5571 1.0000
11.2000 1.2538 1.0000
11.2500 1.7059 1.0000
11.3000 4.1537 1.0000
11.3500 1.5984 1.0000
11.4000 1.6168 1.0000
11.4500 1.4826 1.0000
11.5000 2.4946 1.0000
11.5500 1.9890 1.0000
11.6000 2.4859 1.0000
11.6500 1.7806 1.0000
11.7000 3.5331 1.0000
11.7500 0.8803 1.0000
11.8000 0.5964 1.0000
11.8500 2.6526 1.0000
11.9000 2.9500 1.0000
11.9500 3.2372 1.0000
12.0000 2.1744 1.0000
12.0500 2.0464 1.0000
12.1000 3.6643 1.0000
12.1500 3.6090 1.0000
12.2000 0.7011 1.0000
12.2500 1.9940 1.0000
12.3000 2.3295 1.0000
12.3500 2.3843 1.0000
12.4000 1.7252 1.0000
12.4500 2.9492 1.0000
12.5000 1.7082 1.0000
12.5500 2.4530 1.0000
12.6000 1.6706 1.0000
12.6500 1.6273 1.0000
12.7000 1.0768 1.0000
12.7500 1.3120 1.0000
12.8000 0.8973 1.0000
12.8500 1.3910 1.0000
12.9000 2.7008 1.0000
12.9500 1.2431 1.0000
13.0000 3.1990 1.0000
13.0500 2.9743 1.0000
13.1000 1.6165 1.0000
13.1500 1.3371 1.0000
13.2000 1.3826 1.0000
13.2500 1.7842 1.0000
13.3000 1.2577 1.0000
13.3500 1.8198 1.0000
13.4000 2.4410 1.0000
13.4500 3.4015 1.0000
13.5000 2.8111 1.0000
13.5500 4.0905 1.0000
13.6000 1.9222 1.0000
13.6500 2.3815 1.0000
13.7000 1.8234 1.0000
13.7500 3.1959 1.0000
13.8000 2.0915 1.0000
13.8500 1.1203 1.0000
13.9000 1.9105 1.0000
13.9500 1.0778 1.0000
14.0000 1.0326 1.0000
14.0500 1.4598 1.0000
14.1000 0.9339 1.0000
14.1500 0.6941 1.0000
14.2000 0.8960 1.0000
14.2500 1.1024 1.0000
14.3000 1.5253 1.0000
14.3500 2.7678 1.0000
14.4000 1.9487 1.0000
14.4500 2.2096 1.0000
14.5000 2.2144 1.0000
14.5500 1.5977 1.0000
14.6000 1.2805 1.0000
14.6500 2.7113 1.0000
14.7000 2.0654 1.0000
14.7500 2.3142 1.0000
14.8000 1.1426 1.0000
14.8500 3.8040 1.0000
14.9000 3.2070 1.0000
14.9500 3.0194 1.0000
15.0000 1.6376 1.0000
15.0500 2.7458 1.0000
15.1000 2.8848 1.0000
15.1500 1.8885 1.0000
15.2000 1.7834 1.0000
15.2500 0.8512 1.0000
15.3000 1.9717 1.0000
15.3500 1.5175 1.0000
15.4000 2.4802 1.0000
15.4500 1.8074 1.0000
15.5000 0.9403 1.0000
15.5500 0.9796 1.0000
15.6000 2.2472 1.0000
15.6500 1.1692 1.0000
15.7000 0.6622 1.0000
15.7500 1.5388 1.0000
15.8000 1.3391 1.0000
15.8500 1.4049 1.0000
15.9000 1.7778 1.0000
15.9500 2.0980 1.0000
16.0000 1.1007 1.0000
16.0500 1.4685 1.0000
16.1000 1.8699 1.0000
16.1500 0.9946 1.0000
16.2000 2.0849 1.0000
16.2500 1.1893 1.0000
16.3000 1.8901 1.0000
16.3500 0.8882 1.0000
16.4000 1.3831 1.0000
16.4500 1.3433 1.0000
16.5000 0.4618 1.0000
16.5500 0.9082 1.0000
16.6000 1.0675 1.0000
16.6500 1.5762 1.0000
16.7000 2.7841 1.0000
16.7500 1.3396 1.0000
16.8000 2.6923 1.0000
16.8500 2.4778 1.0000
16.9000 1.3019 1.0000
16.9500 1.5643 1.0000
17.0000 0.9455 1.0000
17.0500 2.1997 1.0000
17.1000 1.9710 1.0000
17.1500 2.3532 1.0000
17.2000 2.8186 1.0000
17.2500 1.4470 1.0000
17.3000 1.5655 1.0000
17.3500 1.3723 1.0000
17.4000 1.0882 1.0000
17.4500 0.7929 1.0000
17.5000 3.1589 1.0000
17.5500 2.6536 1.0000
17.6000 0.7925 1.0000
17.6500 1.3472 1.0000
17.7000 2.0887 1.0000
17.7500 1.9723 1.0000
17.8000 1.3824 1.0000
17.8500 1.3030 1.0000
17.9000 1.9396 1.0000
17.9500 3.1118 1.0000
18.0000 1.6429 1.0000
18.0500 2.0588 1.0000
18.1000 2.2819 1.0000
18.1500 1.7178 1.0000
18.2000 1.3997 1.0000
18.2500 2.0695 1.0000
18.3000 2.0361 1.0000
18.3500 3.3288 1.0000
18.4000 2.5113 1.0000
18.4500 2.5721 1.0000
18.5000 1.8798 1.0000
18.5500 1.5517 1.0000
18.6000 1.8785 1.0000
18.6500 1.4768 1.0000
18.7000 0.6354 1.0000
18.7500 2.8257 1.0000
18.8000 1.3248 1.0000
18.8500 2.1150 1.0000
18.9000 2.5474 1.0000
18.9500 2.7410 1.0000
19.0000 1.6651 1.0000
19.0500 1.9528 1.0000
19.1000 1.5893 1.0000
19.1500 1.2189 1.0000
19.2000 1.9366 1.0000
19.2500 1.9894 1.0000
19.3000 1.6171 1.0000
19.3500 0.8675 1.0000
19.4000 1.0723 1.0000
19.4500 1.6036 1.0000
19.5000 1.7136 1.0000
19.5500 1.4584 1.0000
19.6000 1.3828 1.0000
19.6500 2.2645 1.0000
19.7000 0.9257 1.0000
19.7500 1.3325 1.0000
19.8000 1.5493 1.0000
19.8500 1.6439 1.0000
19.9000 1.1525 1.0000
19.9500 0.8853 1.0000
20.0000 0.8314 1.0000
20.0500 2.2563 1.0000
20.1000 1.3131 1.0000
20.1500 1.1478 1.0000
20.2000 1.6163 1.0000
20.2500 1.8330 1.0000
20.3000 1.9944 1.0000
20.3500 0.9747 1.0000
20.4000 1.0508 1.0000
20.4500 1.3996 1.0000
20.5000 1.0200 1.0000
20.5500 2.8917 1.0000
20.6000 1.2558 1.0000
20.6500 2.9101 1.0000
20.7000 1.2573 1.0000
20.7500 2.0272 1.0000
20.8000 1.3224 1.0000
20.8500 1.1941 1.0000
20.9000 1.3755 1.0000
20.9500 0.8200 1.0000
21.0000 0.7858 1.0000
21.0500 0.4452 1.0000
21.1000 0.8782 1.0000
21.1500 0.8616 1.0000
21.2000 1.5262 1.0000
21.2500 1.6210 1.0000
21.3000 2.0390 1.0000
21.3500 0.5330 1.0000
21.4000 2.1944 1.0000
21.4500 1.1490 1.0000
21.5000 1.2095 1.0000
21.5500 0.5965 1.0000
21.6000 1.7932 1.0000
21.6500 0.8710 1.0000
21.7000 1.2577 1.0000
21.7500 1.9201 1.0000
21.8000 0.9046 1.0000
21.8500 1.3876 1.0000
21.9000 1.6190 1.0000
21.9500 1.7320 1.0000
22.0000 2.6819 1.0000
22.0500 1.5585 1.0000
22.1000 0.6470 1.0000
22.1500 1.2060 1.0000
22.2000 1.7785 1.0000
22.2500 1.5272 1.0000
22.3000 0.8495 1.0000
22.3500 1.0194 1.0000
22.4000 1.2946 1.0000
22.4500 1.5864 1.0000
22.5000 3.2160 1.0000
22.5500 0.8295 1.0000
22.6000 1.8865 1.0000
22.6500 0.7872 1.0000
22.7000 1.3361 1.0000
22.7500 0.7454 1.0000
22.8000 0.8820 1.0000
22.8500 0.9116 1.0000
22.9000 0.6319 1.0000
22.9500 0.5451 1.0000
23.0000 2.0899 1.0000
23.0500 0.5844 1.0000
23.1000 2.0416 1.0000
23.1500 1.3649 1.0000
23.2000 1.7131 1.0000
23.2500 1.9650 1.0000
23.3000 0.2282 1.0000
23.3500 0.7255 1.0000
23.4000 1.4587 1.0000
23.4500 1.7518 1.0000
23.5000 0.9920 1.0000
23.5500 2.2001 1.0000
23.6000 2.9091 1.0000
23.6500 1.7603 1.0000
23.7000 0.5054 1.0000
23.7500 1.7444 1.0000
23.8000 0.9787 1.0000
23.8500 0.3630 1.0000
23.9000 2.0822 1.0000
23.9500 1.3247 1.0000
24.0000 1.3728 1.0000
24.0500 1.8853 1.0000
24.1000 0.7938 1.0000
24.1500 1.8669 1.0000
24.2000 1.6331 1.0000
24.2500 3.2476 1.0000
24.3000 2.2636 1.0000
24.3500 3.7797 1.0000
24.4000 2.9122 1.0000
24.4500 3.4906 1.0000
24.5000 5.2042 1.0000
24.5500 7.1137 1.0000
24.6000 4.2909 1.0000
24.6500 6.0786 1.0000
24.7000 5.2926 1.0000
24.7500 7.0016 1.0000
24.8000 8.9208 1.0000
24.8500 13.4370 1.0000
24.9000 15.7032 1.0000
24.9500 18.7713 1.0000
25.0000 23.8524 1.0000
25.0500 26.4973 1.0000
25.1000 36.3299 1.0000
25.1500 45.2660 1.0000
25.2000 52.8343 1.0000
25.2500 57.7448 1.0000
25.3000 55.8279 1.0000
25.3500 51.8765 1.0000
25.4000 45.1428 1.0000
25.4500 40.7296 1.0000
25.5000 35.1760 1.0000
25.5500 30.7505 1.0000
25.6000 24.8954 1.0000
25.6500 20.0611 1.0000
25.7000 12.9419 1.0000
25.7500 12.1134 1.0000
25.8000 11.6504 1.0000
25.8500 7.3657 1.0000
25.9000 7.8327 1.0000
25.9500 3.7506 1.0000
26.0000 6.5749 1.0000
26.0500 2.9792 1.0000
26.1000 2.8509 1.0000
26.1500 1.9846 1.0000
26.2000 3.9420 1.0000
26.2500 1.9732 1.0000
26.3000 1.6446 1.0000
26.3500 2.0421 1.0000
26.4000 3.0364 1.0000
26.4500 4.5969 1.0000
26.5000 1.9517 1.0000
26.5500 1.0093 1.0000
26.6000 2.9441 1.0000
26.6500 1.3402 1.0000
26.7000 1.5992 1.0000
26.7500 1.6103 1.0000
26.8000 0.7599 1.0000
26.8500 1.7533 1.0000
26.9000 1.6906 1.0000
26.9500 2.1692 1.0000
27.0000 2.4747 1.0000
27.0500 0.8258 1.0000
27.1000 0.1604 1.0000
27.1500 0.5478 1.0000
27.2000 0.7385 1.0000
27.2500 4.1874 1.0000
27.3000 0.9204 1.0000
27.3500 1.1271 1.0000
27.4000 1.4586 1.0000
27.4500 0.7653 1.0000
27.5000 2.3748 1.0000
27.5500 1.6892 1.0000
27.6000 0.4598 1.0000
27.6500 0.5560 1.0000
27.7000 1.0565 1.0000
27.7500 1.4067 1.0000
27.8000 2.2376 1.0000
27.8500 1.8259 1.0000
27.9000 2.2297 1.0000
27.9500 1.1552 1.0000
28.0000 1.5012 1.0000
28.0500 0.3837 1.0000
28.1000 0.7670 1.0000
28.1500 0.3719 1.0000
28.2000 0.9328 1.0000
28.2500 0.4680 1.0000
28.3000 0.5331 1.0000
28.3500 1.0542 1.0000
28.4000 1.5581 1.0000
28.4500 1.9648 1.0000
28.5000 1.0511 1.0000
28.5500 1.4859 1.0000
28.6000 1.1666 1.0000
28.6500 1.1251 1.0000
28.7000 1.5572 1.0000
28.7500 0.5783 1.0000
28.8000 1.5925 1.0000
28.8500 1.1663 1.0000
28.9000 0.2723 1.0000
28.9500 1.5709 1.0000
29.0000 1.0517 1.0000
29.0500 0.0437 1.0000
29.1000 0.2638 1.0000
29.1500 0.5455 1.0000
29.2000 0.4669 1.0000
29.2500 0.6508 1.0000
29.3000 0.9441 1.0000
29.3500 0.0521 1.0000
29.4000 1.4611 1.0000
29.4500 0.7637 1.0000
29.5000 1.1657 1.0000
29.5500 1.1689 1.0000
29.6000 0.6856 1.0000
29.6500 0.8836 1.0000
29.7000 1.1241 1.0000
29.7500 0.0995 1.0000
29.8000 0.8058 1.0000
29.8500 0.4946 1.0000
29.9000 0.5023 1.0000
29.9500 0.9693 1.0000
30.0000 1.0541 1.0000
30.0500 0.5805 1.0000
30.1000 1.0889 1.0000
30.1500 1.9523 1.0000
30.2000 0.7522 1.0000
30.2500 0.9395 1.0000
30.3000 0.7852 1.0000
30.3500 1.3777 1.0000
30.4000 0.0619 1.0000
30.4500 1.0818 1.0000
30.5000 1.0344 1.0000
30.5500 0.7271 1.0000
30.6000 1.1433 1.0000
30.6500 0.0000 1.0000
30.7000 0.9929 1.0000
30.7500 1.9139 1.0000
30.8000 0.7215 1.0000
30.8500 0.3440 1.0000
30.9000 0.9145 1.0000
30.9500 1.5283 1.0000
31.0000 0.7706 1.0000
31.0500 1.5438 1.0000
31.1000 1.2329 1.0000
31.1500 0.8345 1.0000
31.2000 0.7944 1.0000
31.2500 0.7954 1.0000
31.3000 0.5203 1.0000
31.3500 0.7214 1.0000
31.4000 0.4328 1.0000
31.4500 1.1504 1.0000
31.5000 0.8565 1.0000
31.5500 1.5909 1.0000
31.6000 0.6586 1.0000
31.6500 1.5718 1.0000
31.7000 0.1790 1.0000
31.7500 1.2789 1.0000
31.8000 0.4004 1.0000
31.8500 0.4539 1.0000
31.9000 0.0829 1.0000
31.9500 0.4780 1.0000
32.0000 1.0959 1.0000
32.0500 0.1844 1.0000
32.1000 1.0301 1.0000
32.1500 0.5765 1.0000
32.2000 0.9053 1.0000
32.2500 0.7618 1.0000
32.3000 0.6716 1.0000
32.3500 0.5245 1.0000
32.4000 0.6423 1.0000
32.4500 1.1680 1.0000
32.5000 1.5052 1.0000
32.5500 1.1129 1.0000
32.6000 0.3117 1.0000
32.6500 0.2671 1.0000
32.7000 0.7477 1.0000
32.7500 0.1684 1.0000
32.8000 0.4870 1.0000
32.8500 0.4254 1.0000
32.9000 0.3707 1.0000
32.9500 0.8025 1.0000
33.0000 0.0851 1.0000
33.0500 0.0000 1.0000
33.1000 0.5834 1.0000
33.1500 0.5453 1.0000
33.2000 0.2313 1.0000
33.2500 1.6786 1.0000
33.3000 1.0380 1.0000
33.3500 0.9489 1.0000
33.4000 2.4193 1.0000
33.4500 1.2011 1.0000
33.5000 1.2653 1.0000
33.5500 0.1093 1.0000
33.6000 1.1466 1.0000
33.6500 1.5253 1.0000
33.7000 0.4916 1.0000
33.7500 0.9793 1.0000
33.8000 0.0124 1.0000
33.8500 0.5047 1.0000
33.9000 1.3520 1.0000
33.9500 0.5233 1.0000
34.0000 0.7377 1.0000
34.0500 0.0289 1.0000
34.1000 0.1750 1.0000
34.1500 1.1282 1.0000
34.2000 0.0491 1.0000
34.2500 0.7281 1.0000
34.3000 0.9161 1.0000
34.3500 0.8515 1.0000
34.4000 0.7227 1.0000
34.4500 0.8624 1.0000
34.5000 0.5909 1.0000
34.5500 1.0587 1.0000
34.6000 1.6269 1.0000
34.6500 1.0487 1.0000
34.7000 0.4837 1.0000
34.7500 1.2720 1.0000
34.8000 1.1038 1.0000
34.8500 2.0954 1.0000
34.9000 0.6006 1.0000
34.9500 1.3932 1.0000
35.0000 1.1051 1.0000
35.0500 1.0856 1.0000
35.1000 0.6823 1.0000
35.1500 1.6802 1.0000
35.2000 0.0000 1.0000
35.2500 1.7886 1.0000
35.3000 0.3590 1.0000
35.3500 1.3766 1.0000
35.4000 1.7319 1.0000
35.4500 0.5624 1.0000
35.5000 1.9219 1.0000
35.5500 0.8148 1.0000
35.6000 0.3190 1.0000
35.6500 0.9628 1.0000
35.7000 0.5226 1.0000
35.7500 0.5623 1.0000
35.8000 2.0362 1.0000
35.8500 0.4372 1.0000
35.9000 1.5086 1.0000
35.9500 0.9608 1.0000
36.0000 1.4145 1.0000
36.0500 1.4708 1.0000
36.1000 0.4133 1.0000
36.1500 1.0333 1.0000
36.2000 0.6275 1.0000
36.2500 0.0000 1.0000
36.3000 1.8911 1.0000
36.3500 0.3354 1.0000
36.4000 2.3514 1.0000
36.4500 1.4435 1.0000
36.5000 1.2749 1.0000
36.5500 2.6621 1.0000
36.6000 1.6616 1.0000
36.6500 3.5194 1.0000
36.7000 2.5313 1.0000
36.7500 3.4369 1.0000
36.8000 1.9634 1.0000
36.8500 2.1527 1.0000
36.9000 5.3476 1.0000
36.9500 3.8652 1.0000
37.0000 3.9241 1.0000
37.0500 4.9882 1.0000
37.1000 6.2393 1.0000
37.1500 4.5754 1.0000
37.2000 5.3678 1.0000
37.2500 2.7247 1.0000
37.3000 3.6634 1.0000
37.3500 4.0009 1.0000
37.4000 5.7570 1.0000
37.4500 5.7173 1.0000
37.5000 6.3364 1.0000
37.5500 8.7477 1.0000
37.6000 7.2338 1.0000
37.6500 10.6327 1.0000
37.7000 10.1887 1.0000
37.7500 8.9518 1.0000
37.8000 8.6520 1.0000
37.8500 10.1574 1.0000
37.9000 5.7853 1.0000
37.9500 10.2267 1.0000
38.0000 8.9414 1.0000
38.0500 8.7551 1.0000
38.1000 4.8176 1.0000
38.1500 4.3299 1.0000
38.2000 7.1322 1.0000
38.2500 6.7801 1.0000
38.3000 3.5230 1.0000
38.3500 2.7216 1.0000
38.4000 5.0648 1.0000
38.4500 5.5550 1.0000
38.5000 4.0678 1.0000
38.5500 5.8604 1.0000
38.6000 6.5995 1.0000
38.6500 6.4559 1.0000
38.7000 3.3462 1.0000
38.7500 4.1864 1.0000
38.8000 2.6481 1.0000
38.8500 3.4587 1.0000
38.9000 1.2080 1.0000
38.9500 2.3368 1.0000
39.0000 2.5273 1.0000
39.0500 2.5481 1.0000
39.1000 1.8044 1.0000
39.1500 1.8026 1.0000
39.2000 2.7548 1.0000
39.2500 1.1567 1.0000
39.3000 1.3930 1.0000
39.3500 0.6395 1.0000
39.4000 1.1276 1.0000
39.4500 0.5705 1.0000
39.5000 1.9179 1.0000
39.5500 1.0850 1.0000
39.6000 1.8524 1.0000
39.6500 0.4117 1.0000
39.7000 0.0593 1.0000
39.7500 0.5304 1.0000
39.8000 1.3506 1.0000
39.8500 0.2724 1.0000
39.9000 0.4693 1.0000
39.9500 0.5350 1.0000
40.0000 1.0603 1.0000
40.0500 0.4495 1.0000
40.1000 0.2633 1.0000
40.1500 1.4268 1.0000
40.2000 1.6420 1.0000
40.2500 1.4819 1.0000
40.3000 1.1518 1.0000
40.3500 1.4953 1.0000
40.4000 1.6210 1.0000
40.4500 1.6461 1.0000
40.5000 0.0778 1.0000
40.5500 0.2057 1.0000
40.6000 2.0878 1.0000
40.6500 0.6602 1.0000
40.7000 0.0000 1.0000
40.7500 0.0000 1.0000
40.8000 1.1470 1.0000
40.8500 0.6747 1.0000
40.9000 0.8588 1.0000
40.9500 0.7036 1.0000
41.0000 0.7089 1.0000
41.0500 0.6246 1.0000
41.1000 0.0997 1.0000
41.1500 0.5337 1.0000
41.2000 0.2992 1.0000
41.2500 1.5687 1.0000
41.3000 0.8681 1.0000
41.3500 1.0669 1.0000
41.4000 0.4719 1.0000
41.4500 0.5158 1.0000
41.5000 1.2276 1.0000
41.5500 0.3451 1.0000
41.6000 0.0000 1.0000
41.6500 0.0000 1.0000
41.7000 1.3588 1.0000
41.7500 0.1733 1.0000
41.8000 0.3454 1.0000
41.8500 0.7601 1.0000
41.9000 1.3413 1.0000
41.9500 0.8631 1.0000
42.0000 0.5199 1.0000
42.0500 0.4688 1.0000
42.1000 1.1283 1.0000
42.1500 0.5592 1.0000
42.2000 0.9491 1.0000
42.2500 0.3814 1.0000
42.3000 0.3546 1.0000
42.3500 0.5235 1.0000
42.4000 0.3174 1.0000
42.4500 0.0648 1.0000
42.5000 0.5224 1.0000
42.5500 0.6085 1.0000
42.6000 0.1380 1.0000
42.6500 0.3527 1.0000
42.7000 0.0349 1.0000
42.7500 0.3061 1.0000
42.8000 0.0000 1.0000
42.8500 0.4269 1.0000
42.9000 0.0963 1.0000
42.9500 0.0698 1.0000
43.0000 0.0000 1.0000
43.0500 1.5347 1.0000
43.1000 0.0000 1.0000
43.1500 1.0609 1.0000
43.2000 1.4775 1.0000
43.2500 0.2465 1.0000
43.3000 0.7145 1.0000
43.3500 0.7158 1.0000
43.4000 1.1088 1.0000
43.4500 0.2509 1.0000
43.5000 0.9991 1.0000
43.5500 0.0000 1.0000
43.6000 1.4837 1.0000
43.6500 0.6101 1.0000
43.7000 0.4104 1.0000
43.7500 0.6941 1.0000
43.8000 1.3454 1.0000
43.8500 1.2760 1.0000
43.9000 1.2519 1.0000
43.9500 0.2235 1.0000
44.0000 1.6311 1.0000
44.0500 0.7000 1.0000
44.1000 1.0385 1.0000
44.1500 0.0000 1.0000
44.2000 0.2643 1.0000
44.2500 0.1320 1.0000
44.3000 0.0000 1.0000
44.3500 1.0628 1.0000
44.4000 0.1823 1.0000
44.4500 1.0458 1.0000
44.5000 0.0000 1.0000
44.5500 0.2638 1.0000
44.6000 0.9138 1.0000
44.6500 2.0284 1.0000
44.7000 0.2832 1.0000
44.7500 0.5692 1.0000
44.8000 0.1711 1.0000
44.8500 0.2934 1.0000
44.9000 0.4742 1.0000
44.9500 1.1179 1.0000
45.0000 0.6061 1.0000
45.0500 1.7561 1.0000
45.1000 0.6667 1.0000
45.1500 0.8716 1.0000
45.2000 0.6815 1.0000
45.2500 1.2149 1.0000
45.3000 0.4844 1.0000
45.3500 0.1483 1.0000
45.4000 1.0456 1.0000
45.4500 1.0639 1.0000
45.5000 0.7171 1.0000
45.5500 0.8393 1.0000
45.6000 0.3316 1.0000
45.6500 1.0845 1.0000
45.7000 0.4951 1.0000
45.7500 1.3898 1.0000
45.8000 0.5672 1.0000
45.8500 1.2956 1.0000
45.9000 0.8058 1.0000
45.9500 1.1260 1.0000
46.0000 1.6995 1.0000
46.0500 1.0191 1.0000
46.1000 0.0139 1.0000
46.1500 0.5556 1.0000
46.2000 1.2868 1.0000
46.2500 1.3759 1.0000
46.3000 0.7647 1.0000
46.3500 1.3573 1.0000
46.4000 0.5848 1.0000
46.4500 1.8103 1.0000
46.5000 2.0514 1.0000
46.5500 0.8601 1.0000
46.6000 1.1554 1.0000
46.6500 0.5226 1.0000
46.7000 1.1735 1.0000
46.7500 1.0335 1.0000
46.8000 1.1568 1.0000
46.8500 0.4865 1.0000
46.9000 1.5254 1.0000
46.9500 0.2602 1.0000
47.0000 1.4533 1.0000
47.0500 1.4376 1.0000
47.1000 2.1514 1.0000
47.1500 1.0076 1.0000
47.2000 1.0475 1.0000
47.2500 1.3560 1.0000
47.3000 2.3210 1.0000
47.3500 1.5708 1.0000
47.4000 2.1687 1.0000
47.4500 3.7286 1.0000
47.5000 2.6802 1.0000
47.5500 4.7910 1.0000
47.6000 4.9091 1.0000
47.6500 3.7166 1.0000
47.7000 5.9482 1.0000
47.7500 7.9952 1.0000
47.8000 7.5396 1.0000
47.8500 15.2645 1.0000
47.9000 11.0594 1.0000
47.9500 14.8365 1.0000
48.0000 18.0341 1.0000
48.0500 16.0832 1.0000
48.1000 13.9767 1.0000
48.1500 16.4179 1.0000
48.2000 13.1274 1.0000
48.2500 11.0268 1.0000
48.3000 9.4785 1.0000
48.3500 7.4785 1.0000
48.4000 3.8063 1.0000
48.4500 7.1602 1.0000
48.5000 3.5870 1.0000
48.5500 3.2711 1.0000
48.6000 1.4161 1.0000
48.6500 2.7855 1.0000
48.7000 1.9663 1.0000
48.7500 0.7378 1.0000
48.8000 1.7881 1.0000
48.8500 0.5447 1.0000
48.9000 1.3232 1.0000
48.9500 2.3841 1.0000
49.0000 0.4628 1.0000
49.0500 1.7491 1.0000
49.1000 0.5764 1.0000
49.1500 0.3645 1.0000
49.2000 0.4893 1.0000
49.2500 0.0537 1.0000
49.3000 0.3978 1.0000
49.3500 0.0000 1.0000
49.4000 0.5188 1.0000
49.4500 0.2096 1.0000
49.5000 0.7014 1.0000
49.5500 1.4626 1.0000
49.6000 1.0474 1.0000
49.6500 0.0705 1.0000
49.7000 0.7187 1.0000
49.7500 0.2472 1.0000
49.8000 1.0798 1.0000
49.8500 1.1178 1.0000
49.9000 0.8403 1.0000
49.9500 1.0440 1.0000
50.0000 0.4507 1.0000
50.0500 0.5256 1.0000
50.1000 0.0977 1.0000
50.1500 0.0508 1.0000
50.2000 0.8622 1.0000
50.2500 2.2329 1.0000
50.3000 0.5189 1.0000
50.3500 1.0006 1.0000
50.4000 0.9184 1.0000
50.4500 0.4022 1.0000
50.5000 0.5585 1.0000
50.5500 0.0044 1.0000
50.6000 0.0711 1.0000
50.6500 0.4991 1.0000
50.7000 1.5758 1.0000
50.7500 1.0312 1.0000
50.8000 0.0574 1.0000
50.8500 1.6662 1.0000
50.9000 0.8706 1.0000
50.9500 0.5298 1.0000
51.0000 1.3141 1.0000
51.0500 2.4253 1.0000
51.1000 0.9508 1.0000
51.1500 0.4171 1.0000
51.2000 0.0000 1.0000
51.2500 1.0273 1.0000
51.3000 0.1374 1.0000
51.3500 0.0617 1.0000
51.4000 0.2621 1.0000
51.4500 0.6640 1.0000
51.5000 0.4078 1.0000
51.5500 0.5548 1.0000
51.6000 0.0159 1.0000
51.6500 0.7586 1.0000
51.7000 1.2490 1.0000
51.7500 0.5871 1.0000
51.8000 1.1252 1.0000
51.8500 0.5163 1.0000
51.9000 0.6419 1.0000
51.9500 0.6495 1.0000
52.0000 1.0014 1.0000
52.0500 1.3345 1.0000
52.1000 0.9905 1.0000
52.1500 0.2897 1.0000
52.2000 0.5220 1.0000
52.2500 0.0029 1.0000
52.3000 0.9871 1.0000
52.3500 0.5376 1.0000
52.4000 1.5845 1.0000
52.4500 1.3025 1.0000
52.5000 1.7256 1.0000
52.5500 0.8597 1.0000
52.6000 0.1722 1.0000
52.6500 1.2071 1.0000
52.7000 1.4294 1.0000
52.7500 1.0952 1.0000
52.8000 1.5136 1.0000
52.8500 0.6734 1.0000
52.9000 0.5034 1.0000
52.9500 0.5280 1.0000
53.0000 1.3053 1.0000
53.0500 0.0186 1.0000
53.1000 1.5589 1.0000
53.1500 3.4753 1.0000
53.2000 1.1584 1.0000
53.2500 3.0138 1.0000
53.3000 2.3100 1.0000
53.3500 3.2123 1.0000
53.4000 3.8465 1.0000
53.4500 3.4104 1.0000
53.5000 5.3268 1.0000
53.5500 3.1820 1.0000
53.6000 4.2375 1.0000
53.6500 3.6886 1.0000
53.7000 7.5249 1.0000
53.7500 5.0835 1.0000
53.8000 4.6076 1.0000
53.8500 7.8528 1.0000
53.9000 6.4719 1.0000
53.9500 8.0925 1.0000
54.0000 7.0998 1.0000
54.0500 7.2944 1.0000
54.1000 6.2284 1.0000
54.1500 7.0196 1.0000
54.2000 4.9436 1.0000
54.2500 2.9630 1.0000
54.3000 4.0699 1.0000
54.3500 4.1091 1.0000
54.4000 3.4669 1.0000
54.4500 4.6367 1.0000
54.5000 4.0754 1.0000
54.5500 3.5271 1.0000
54.6000 4.9088 1.0000
54.6500 4.9056 1.0000
54.7000 4.5369 1.0000
54.7500 5.3827 1.0000
54.8000 7.8833 1.0000
54.8500 12.2385 1.0000
54.9000 6.5996 1.0000
54.9500 10.2463 1.0000
55.0000 7.9334 1.0000
55.0500 10.4921 1.0000
55.1000 10.3491 1.0000
55.1500 7.1693 1.0000
55.2000 7.4783 1.0000
55.2500 7.0846 1.0000
55.3000 8.0323 1.0000
55.3500 5.8050 1.0000
55.4000 3.6956 1.0000
55.4500 3.2083 1.0000
55.5000 3.3285 1.0000
55.5500 2.9169 1.0000
55.6000 2.5003 1.0000
55.6500 2.8096 1.0000
55.7000 1.7551 1.0000
55.7500 2.3275 1.0000
55.8000 1.2194 1.0000
55.8500 2.0151 1.0000
55.9000 1.4736 1.0000
55.9500 1.5078 1.0000
56.0000 1.3100 1.0000
56.0500 0.4438 1.0000
56.1000 1.6131 1.0000
56.1500 0.6859 1.0000
56.2000 0.9887 1.0000
56.2500 0.8093 1.0000
56.3000 0.5335 1.0000
56.3500 0.3496 1.0000
56.4000 1.0028 1.0000
56.4500 2.4859 1.0000
56.5000 0.4017 1.0000
56.5500 0.6103 1.0000
56.6000 0.4846 1.0000
56.6500 1.2438 1.0000
56.7000 1.2201 1.0000
56.7500 1.2907 1.0000
56.8000 1.5491 1.0000
56.8500 0.2984 1.0000
56.9000 0.7899 1.0000
56.9500 0.1485 1.0000
57.0000 0.4469 1.0000
57.0500 0.6931 1.0000
57.1000 1.0697 1.0000
57.1500 1.1269 1.0000
57.2000 0.4285 1.0000
57.2500 1.3996 1.0000
57.3000 0.6630 1.0000
57.3500 0.0205 1.0000
57.4000 0.8162 1.0000
57.4500 0.7084 1.0000
57.5000 0.5789 1.0000
57.5500 0.7955 1.0000
57.6000 0.5924 1.0000
57.6500 0.2651 1.0000
57.7000 0.5310 1.0000
57.7500 0.1846 1.0000
57.8000 0.0000 1.0000
57.8500 1.0515 1.0000
57.9000 1.1925 1.0000
57.9500 0.4287 1.0000
58.0000 0.4878 1.0000
58.0500 0.0000 1.0000
58.1000 0.3869 1.0000
58.1500 0.0000 1.0000
58.2000 1.1313 1.0000
58.2500 0.0279 1.0000
58.3000 1.3902 1.0000
58.3500 0.3077 1.0000
58.4000 1.0870 1.0000
58.4500 0.3048 1.0000
58.5000 0.3962 1.0000
58.5500 0.5332 1.0000
58.6000 0.7855 1.0000
58.6500 2.2575 1.0000
58.7000 1.0583 1.0000
58.7500 0.9211 1.0000
58.8000 0.0210 1.0000
58.8500 0.2990 1.0000
58.9000 0.5467 1.0000
58.9500 0.0636 1.0000
59.0000 0.3329 1.0000
59.0500 1.2016 1.0000
59.1000 0.6449 1.0000
59.1500 0.0490 1.0000
59.2000 0.5425 1.0000
59.2500 0.6106 1.0000
59.3000 0.0734 1.0000
59.3500 0.1685 1.0000
59.4000 0.3846 1.0000
59.4500 1.0459 1.0000
59.5000 0.5248 1.0000
59.5500 0.0000 1.0000
59.6000 0.0791 1.0000
59.6500 0.2535 1.0000
59.7000 0.0595 1.0000
59.7500 0.2593 1.0000
59.8000 0.2851 1.0000
59.8500 1.5294 1.0000
59.9000 1.0071 1.0000
59.9500 1.0096 1.0000
60.0000 0.1076 1.0000
60.0500 0.9391 1.0000
60.1000 0.0298 1.0000
60.1500 0.5875 1.0000
60.2000 0.5174 1.0000
60.2500 0.9065 1.0000
60.3000 1.0607 1.0000
60.3500 0.7129 1.0000
60.4000 1.2029 1.0000
60.4500 1.3795 1.0000
60.5000 0.5439 1.0000
60.5500 2.0560 1.0000
60.6000 0.5808 1.0000
60.6500 0.6618 1.0000
60.7000 0.3058 1.0000
60.7500 0.0328 1.0000
60.8000 0.6452 1.0000
60.8500 0.4708 1.0000
60.9000 0.5334 1.0000
60.9500 1.6915 1.0000
61.0000 0.6183 1.0000
61.0500 0.6119 1.0000
61.1000 1.1078 1.0000
61.1500 0.3467 1.0000
61.2000 0.6557 1.0000
61.2500 0.2134 1.0000
61.3000 2.0482 1.0000
61.3500 0.7903 1.0000
61.4000 0.5484 1.0000
61.4500 1.3930 1.0000
61.5000 1.3359 1.0000
61.5500 2.0832 1.0000
61.6000 1.3930 1.0000
61.6500 0.5559 1.0000
61.7000 0.6260 1.0000
61.7500 1.5423 1.0000
61.8000 1.2629 1.0000
61.8500 0.5292 1.0000
61.9000 1.7707 1.0000
61.9500 2.8382 1.0000
62.0000 2.2594 1.0000
62.0500 1.5370 1.0000
62.1000 3.7529 1.0000
62.1500 1.6623 1.0000
62.2000 3.3306 1.0000
62.2500 1.7947 1.0000
62.3000 2.6828 1.0000
62.3500 3.9261 1.0000
62.4000 4.3778 1.0000
62.4500 4.3677 1.0000
62.5000 4.4455 1.0000
62.5500 6.5458 1.0000
62.6000 6.5823 1.0000
62.6500 6.7777 1.0000
62.7000 3.8637 1.0000
62.7500 8.2734 1.0000
62.8000 6.5853 1.0000
62.8500 4.3411 1.0000
62.9000 3.0553 1.0000
62.9500 4.8735 1.0000
63.0000 5.1841 1.0000
63.0500 4.1932 1.0000
63.1000 1.9592 1.0000
63.1500 4.5869 1.0000
63.2000 1.6257 1.0000
63.2500 1.6082 1.0000
63.3000 2.0227 1.0000
63.3500 1.5848 1.0000
63.4000 1.5034 1.0000
63.4500 0.2281 1.0000
63.5000 1.0588 1.0000
63.5500 0.6439 1.0000
63.6000 0.4453 1.0000
63.6500 0.5328 1.0000
63.7000 0.5024 1.0000
63.7500 0.1526 1.0000
63.8000 0.9143 1.0000
63.8500 0.7223 1.0000
63.9000 0.5122 1.0000
63.9500 1.6199 1.0000
64.0000 0.2432 1.0000
64.0500 0.5621 1.0000
64.1000 0.8961 1.0000
64.1500 0.5662 1.0000
64.2000 0.3065 1.0000
64.2500 0.0000 1.0000
64.3000 1.6717 1.0000
64.3500 0.0758 1.0000
64.4000 0.5168 1.0000
64.4500 1.0602 1.0000
64.5000 0.7922 1.0000
64.5500 0.0155 1.0000
64.6000 0.5314 1.0000
64.6500 0.5225 1.0000
64.7000 1.0727 1.0000
64.7500 0.2655 1.0000
64.8000 0.6777 1.0000
64.8500 0.4393 1.0000
64.9000 1.1590 1.0000
64.9500 0.6620 1.0000
65.0000 0.0000 1.0000
65.0500 0.9517 1.0000
65.1000 0.7609 1.0000
65.1500 0.6673 1.0000
65.2000 0.0000 1.0000
65.2500 0.5281 1.0000
65.3000 0.8243 1.0000
65.3500 0.4867 1.0000
65.4000 0.8644 1.0000
65.4500 0.1071 1.0000
65.5000 0.9139 1.0000
65.5500 1.0536 1.0000
65.6000 0.0052 1.0000
65.6500 0.4127 1.0000
65.7000 0.7997 1.0000
65.7500 0.0000 1.0000
65.8000 0.0000 1.0000
65.8500 2.0823 1.0000
65.9000 0.1516 1.0000
65.9500 0.7014 1.0000
66.0000 0.5284 1.0000
66.0500 0.4557 1.0000
66.1000 1.1328 1.0000
66.1500 0.4921 1.0000
66.2000 0.5112 1.0000
66.2500 1.5119 1.0000
66.3000 0.0000 1.0000
66.3500 0.1437 1.0000
66.4000 1.0153 1.0000
66.4500 0.0000 1.0000
66.5000 0.0688 1.0000
66.5500 0.5243 1.0000
66.6000 0.2983 1.0000
66.6500 0.0155 1.0000
66.7000 0.1369 1.0000
66.7500 0.6195 1.0000
66.8000 0.6829 1.0000
66.8500 0.2352 1.0000
66.9000 0.2654 1.0000
66.9500 0.3202 1.0000
67.0000 0.3288 1.0000
67.0500 0.5993 1.0000
67.1000 0.2402 1.0000
67.1500 0.5892 1.0000
67.2000 0.2274 1.0000
67.2500 0.2070 1.0000
67.3000 1.0492 1.0000
67.3500 0.3038 1.0000
67.4000 0.7768 1.0000
67.4500 0.5806 1.0000
67.5000 0.5301 1.0000
67.5500 0.7097 1.0000
67.6000 0.7742 1.0000
67.6500 0.0000 1.0000
67.7000 1.0240 1.0000
67.7500 0.7196 1.0000
67.8000 0.5117 1.0000
67.8500 0.9476 1.0000
67.9000 1.5150 1.0000
67.9500 1.8709 1.0000
68.0000 1.0639 1.0000
68.0500 1.1327 1.0000
68.1000 1.0053 1.0000
68.1500 0.8970 1.0000
68.2000 2.2796 1.0000
68.2500 0.8201 1.0000
68.3000 1.5193 1.0000
68.3500 1.0490 1.0000
68.4000 0.9024 1.0000
68.4500 1.0339 1.0000
68.5000 2.0799 1.0000
68.5500 0.3337 1.0000
68.6000 1.6372 1.0000
68.6500 1.7604 1.0000
68.7000 1.4651 1.0000
68.7500 0.8357 1.0000
68.8000 2.2677 1.0000
68.8500 2.5117 1.0000
68.9000 2.6600 1.0000
68.9500 3.1043 1.0000
69.0000 1.2403 1.0000
69.0500 1.1754 1.0000
69.1000 1.3814 1.0000
69.1500 1.8115 1.0000
69.2000 2.0997 1.0000
69.2500 2.4785 1.0000
69.3000 0.5691 1.0000
69.3500 0.9711 1.0000
69.4000 1.0438 1.0000
69.4500 2.3692 1.0000
69.5000 1.9895 1.0000
69.5500 0.2377 1.0000
69.6000 0.2314 1.0000
69.6500 0.5408 1.0000
69.7000 0.5689 1.0000
69.7500 2.1582 1.0000
69.8000 1.5896 1.0000
69.8500 2.2393 1.0000
69.9000 0.2731 1.0000
69.9500 3.9332 1.0000
70.0000 2.6556 1.0000
70.0500 1.7338 1.0000
70.1000 2.8435 1.0000
70.1500 1.7147 1.0000
70.2000 3.6288 1.0000
70.2500 4.0107 1.0000
70.3000 2.7744 1.0000
70.3500 2.0027 1.0000
70.4000 3.0425 1.0000
70.4500 5.2228 1.0000
70.5000 2.9847 1.0000
70.5500 2.5275 1.0000
70.6000 1.4029 1.0000
70.6500 0.6117 1.0000
70.7000 0.5401 1.0000
70.7500 1.3404 1.0000
70.8000 0.4015 1.0000
70.8500 1.4191 1.0000
70.9000 0.5113 1.0000
70.9500 2.0456 1.0000
71.0000 2.0847 1.0000
71.0500 0.1968 1.0000
71.1000 0.5268 1.0000
71.1500 0.6482 1.0000
71.2000 0.3854 1.0000
71.2500 0.0000 1.0000
71.3000 0.5637 1.0000
71.3500 0.0131 1.0000
71.4000 0.8393 1.0000
71.4500 0.2231 1.0000
71.5000 0.0474 1.0000
71.5500 0.3331 1.0000
71.6000 0.9657 1.0000
71.6500 0.6585 1.0000
71.7000 0.6290 1.0000
71.7500 0.0000 1.0000
71.8000 0.1080 1.0000
71.8500 0.3957 1.0000
71.9000 0.0000 1.0000
71.9500 0.0857 1.0000
72.0000 0.0189 1.0000
72.0500 0.4341 1.0000
72.1000 0.2903 1.0000
72.1500 0.5194 1.0000
72.2000 0.3166 1.0000
72.2500 0.4670 1.0000
72.3000 0.5900 1.0000
72.3500 0.5961 1.0000
72.4000 0.0000 1.0000
72.4500 0.3385 1.0000
72.5000 0.9618 1.0000
72.5500 0.0000 1.0000
72.6000 0.5230 1.0000
72.6500 0.3563 1.0000
72.7000 1.0671 1.0000
72.7500 0.7434 1.0000
72.8000 0.1715 1.0000
72.8500 0.7697 1.0000
72.9000 0.1647 1.0000
72.9500 0.5794 1.0000
73.0000 0.8110 1.0000
73.0500 0.8415 1.0000
73.1000 0.3990 1.0000
73.1500 0.3466 1.0000
73.2000 0.1647 1.0000
73.2500 0.7476 1.0000
73.3000 0.1253 1.0000
73.3500 0.5965 1.0000
73.4000 0.8864 1.0000
73.4500 0.5225 1.0000
73.5000 0.1795 1.0000
73.5500 0.9296 1.0000
73.6000 0.5281 1.0000
73.6500 1.6733 1.0000
73.7000 0.9246 1.0000
73.7500 1.1822 1.0000
73.8000 0.7703 1.0000
73.8500 0.7125 1.0000
73.9000 0.9610 1.0000
73.9500 1.0586 1.0000
74.0000 1.0471 1.0000
74.0500 0.8339 1.0000
74.1000 1.5935 1.0000
74.1500 1.7762 1.0000
74.2000 1.0675 1.0000
74.2500 0.7332 1.0000
74.3000 1.3802 1.0000
74.3500 1.3019 1.0000
74.4000 1.7395 1.0000
74.4500 1.6711 1.0000
74.5000 1.9067 1.0000
74.5500 1.5860 1.0000
74.6000 1.3725 1.0000
74.6500 2.4387 1.0000
74.7000 1.5927 1.0000
74.7500 2.0906 1.0000
74.8000 2.9755 1.0000
74.8500 3.8981 1.0000
74.9000 5.8718 1.0000
74.9500 3.8896 1.0000
75.0000 2.8588 1.0000
75.0500 3.7071 1.0000
75.1000 2.6428 1.0000
75.1500 3.7109 1.0000
75.2000 3.1498 1.0000
75.2500 4.2227 1.0000
75.3000 2.0955 1.0000
75.3500 2.1441 1.0000
75.4000 3.9259 1.0000
75.4500 1.9615 1.0000
75.5000 1.4598 1.0000
75.5500 3.0935 1.0000
75.6000 1.1834 1.0000
75.6500 1.5481 1.0000
75.7000 1.3250 1.0000
75.7500 3.1085 1.0000
75.8000 2.0916 1.0000
75.8500 2.0682 1.0000
75.9000 2.5418 1.0000
75.9500 1.1680 1.0000
76.0000 1.6225 1.0000
76.0500 2.6225 1.0000
76.1000 1.8915 1.0000
76.1500 1.3354 1.0000
76.2000 1.0513 1.0000
76.2500 1.1169 1.0000
76.3000 0.8837 1.0000
76.3500 1.2455 1.0000
76.4000 1.2965 1.0000
76.4500 1.3178 1.0000
76.5000 1.7326 1.0000
76.5500 0.6806 1.0000
76.6000 1.0753 1.0000
76.6500 0.4157 1.0000
76.7000 0.5911 1.0000
76.7500 1.0510 1.0000
76.8000 0.2253 1.0000
76.8500 0.0000 1.0000
76.9000 0.8881 1.0000
76.9500 1.2879 1.0000
77.0000 0.2381 1.0000
77.0500 0.2477 1.0000
77.1000 0.0753 1.0000
77.1500 0.5663 1.0000
77.2000 0.4735 1.0000
77.2500 0.0002 1.0000
77.3000 0.0000 1.0000
77.3500 0.9288 1.0000
77.4000 0.1571 1.0000
77.4500 0.0000 1.0000
77.5000 0.5409 1.0000
77.5500 0.3734 1.0000
77.6000 0.9136 1.0000
77.6500 1.1922 1.0000
77.7000 0.3752 1.0000
77.7500 0.4245 1.0000
77.8000 0.0000 1.0000
77.8500 0.8370 1.0000
77.9000 0.6862 1.0000
77.9500 0.1804 1.0000
78.0000 0.1423 1.0000
78.0500 0.5076 1.0000
78.1000 0.3526 1.0000
78.1500 0.1976 1.0000
78.2000 0.3831 1.0000
78.2500 0.1879 1.0000
78.3000 1.1889 1.0000
78.3500 0.0000 1.0000
78.4000 0.3592 1.0000
78.4500 0.5795 1.0000
78.5000 1.5415 1.0000
78.5500 0.4931 1.0000
78.6000 0.5998 1.0000
78.6500 1.7472 1.0000
78.7000 0.5560 1.0000
78.7500 0.5274 1.0000
78.8000 0.6892 1.0000
78.8500 0.0000 1.0000
78.9000 0.6456 1.0000
78.9500 0.0121 1.0000
79.0000 0.8942 1.0000
79.0500 0.0425 1.0000
79.1000 0.0462 1.0000
79.1500 0.2756 1.0000
79.2000 0.5293 1.0000
79.2500 0.9084 1.0000
79.3000 1.2647 1.0000
79.3500 0.0237 1.0000
79.4000 0.4191 1.0000
79.4500 0.2039 1.0000
79.5000 0.5274 1.0000
79.5500 0.5218 1.0000
79.6000 0.0078 1.0000
79.6500 0.8033 1.0000
79.7000 0.1470 1.0000
79.7500 0.4683 1.0000
79.8000 0.6955 1.0000
79.8500 0.6648 1.0000
79.9000 1.0551 1.0000
79.9500 0.2401 1.0000
79.9800 0.6751 1.0000
*RAS_INT_END
*RAS_DATA_END